Workbook

Sheet Cover
B2: Variance-to-Action FP&A Model
B3: Fictional Indian D2C brand · FY27 budget, variance analysis and rolling forecast
B4: Prepared by | C4: Debayan Bandyopadhyay
B5: The company is FICTIONAL. Cost ratios are benchmarked to Honasa Consumer FY26 public disclosures; no real company financials are represented.
B7: Snapshot
B8: FY26 net revenue (₹ crore) | F8: ='Historical Data'!AB12/100 -> 399.99959
B9: FY26 EBITDA margin | F9: ='Historical Data'!AB40 -> 0.10024407
B10: FY27 budget net revenue (₹ crore) | F10: ='Assumptions & Budget'!O67/100 -> 453.4469
B11: FY27 budget EBITDA margin | F11: ='Assumptions & Budget'!O95 -> 0.11815857
B12: FY27 rolling forecast net revenue (₹ crore) | F12: ='Rolling Forecast'!O12/100 -> 455.37875
B13: FY27 rolling forecast EBITDA margin | F13: ='Rolling Forecast'!O40 -> 0.1125173
B14: Actuals loaded through | F14: ='Assumptions & Budget'!$C$6 -> 46266
B16: Workbook map
B17: Executive Dashboard | C17: One-page view: KPI tiles, two EBITDA bridges, variance by cause, monthly margin trend
B18: Historical Data | C18: 24 months of synthetic history across Sales, Operations, Marketing, HR, IT and Finance
B19: Assumptions & Budget | C19: All drivers in labelled cells; monthly FY27 budget built from them
B20: Actual vs Budget | C20: Actuals input, flexed budget, ₹ variances (favourable = +), revenue volume vs price split
B21: Variance-to-Action Log | C21: Materiality test, Timing / One-off / Structural classification, action and override
B22: Rolling Forecast | C22: Actuals to date + forecast re-based for structural variances, timing reversals and cuts
B23: Summary | C23: YTD result, FY27 outlook, log statistics, top adverse variances, integrity checks
B24: Model Notes | C24: Method, benchmark, assumptions, limitations
B25: Colour code
B26: Blue text | C26: Hard-coded input or assumption
B27: Black text | C27: Formula
B28: Green text | C28: Direct link from another sheet
B29: Yellow fill | C29: Key assumption to flex

Sheet Executive Dashboard
A1: Executive Dashboard – FY27 Budget, Performance and Outlook
A2: ="Decision view · ₹ lakh unless stated · Actuals loaded through "&TEXT('Assumptions & Budget'!$C$6,"mmm-yy") -> Decision view · ₹ lakh unless stated · Actuals loaded through Sep-26
A4: FY27 budget revenue (₹ crore) | B4: FY27 forecast revenue (₹ crore) | D4: YTD EBITDA vs budget (₹ lakh) | F4: FY27 budget EBITDA margin | H4: FY27 forecast EBITDA margin | J4: Material variances (no.)
A5: ='Assumptions & Budget'!O67/100 -> 453.4469 | B5: ='Rolling Forecast'!O12/100 -> 455.37875 | D5: ='Actual vs Budget'!O143 -> -413.17006 | F5: ='Assumptions & Budget'!O95 -> 0.11815857 | H5: ='Rolling Forecast'!O40 -> 0.1125173 | J5: ='Variance-to-Action Log'!C27 -> 8
A40: Reading the charts: green = favourable, red = unfavourable, navy = totals. Bridges tie to the model (check cells in the chart data below). The cause chart uses the trigger variance from the Variance-to-Action Log.
A48: Chart data (formulas only; feeds the charts above)
A50: Step | B50: Value | C50: Cumulative | D50: Base (hidden) | E50: Increase | F50: Decrease | G50: Total
A51: Budget | B51: ='Actual vs Budget'!O87 -> 2299.0598 | C51: =B51 -> 2299.0598 | D51: =0 -> 0 | E51: =0 -> 0 | F51: =0 -> 0 | G51: =B51 -> 2299.0598
A52: Revenue | B52: ='Actual vs Budget'!O119 -> 193.18544 | C52: =C51+B52 -> 2492.2452 | D52: =MIN(C51,C52) -> 2299.0598 | E52: =MAX(B52,0) -> 193.18544 | F52: =MAX(-B52,0) -> 0 | G52: =0 -> 0
A53: COGS | B53: ='Actual vs Budget'!O120 -> 115.68834 | C53: =C52+B53 -> 2607.9336 | D53: =MIN(C52,C53) -> 2492.2452 | E53: =MAX(B53,0) -> 115.68834 | F53: =MAX(-B53,0) -> 0 | G53: =0 -> 0
A54: Sales | B54: ='Actual vs Budget'!O124 -> -83.749698 | C54: =C53+B54 -> 2524.1839 | D54: =MIN(C53,C54) -> 2524.1839 | E54: =MAX(B54,0) -> 0 | F54: =MAX(-B54,0) -> 83.749698 | G54: =0 -> 0
A55: Operations | B55: ='Actual vs Budget'!O128 -> -193.17242 | C55: =C54+B55 -> 2331.0115 | D55: =MIN(C54,C55) -> 2331.0115 | E55: =MAX(B55,0) -> 0 | F55: =MAX(-B55,0) -> 193.17242 | G55: =0 -> 0
A56: Marketing | B56: ='Actual vs Budget'!O132 -> -366.01186 | C56: =C55+B56 -> 1964.9996 | D56: =MIN(C55,C56) -> 1964.9996 | E56: =MAX(B56,0) -> 0 | F56: =MAX(-B56,0) -> 366.01186 | G56: =0 -> 0
A57: IT | B57: ='Actual vs Budget'!O138 -> -82.827355 | C57: =C56+B57 -> 1882.1722 | D57: =MIN(C56,C57) -> 1882.1722 | E57: =MAX(B57,0) -> 0 | F57: =MAX(-B57,0) -> 82.827355 | G57: =0 -> 0
A58: HR + Finance | B58: ='Actual vs Budget'!O135+'Actual vs Budget'!O141 -> 3.7175 | C58: =C57+B58 -> 1885.8897 | D58: =MIN(C57,C58) -> 1882.1722 | E58: =MAX(B58,0) -> 3.7175 | F58: =MAX(-B58,0) -> 0 | G58: =0 -> 0
A59: Actual | B59: ='Actual vs Budget'!O40 -> 1885.8897 | C59: =B59 -> 1885.8897 | D59: =0 -> 0 | E59: =0 -> 0 | F59: =0 -> 0 | G59: =B59 -> 1885.8897
A60: Tie-out (should be 0) | B60: =ROUND(C58-B59,3) -> 0
A63: Cause | B63: Adverse (₹ lakh) | C63: Favourable (₹ lakh)
A64: Timing | B64: =SUMIFS('Variance-to-Action Log'!$X$8:$X$23,'Variance-to-Action Log'!$O$8:$O$23,A64,'Variance-to-Action Log'!$X$8:$X$23,"<0") -> -192.53862 | C64: =SUMIFS('Variance-to-Action Log'!$X$8:$X$23,'Variance-to-Action Log'!$O$8:$O$23,A64,'Variance-to-Action Log'!$X$8:$X$23,">0") -> 0
A65: One-off | B65: =SUMIFS('Variance-to-Action Log'!$X$8:$X$23,'Variance-to-Action Log'!$O$8:$O$23,A65,'Variance-to-Action Log'!$X$8:$X$23,"<0") -> -153.931 | C65: =SUMIFS('Variance-to-Action Log'!$X$8:$X$23,'Variance-to-Action Log'!$O$8:$O$23,A65,'Variance-to-Action Log'!$X$8:$X$23,">0") -> 0
A66: Structural | B66: =SUMIFS('Variance-to-Action Log'!$X$8:$X$23,'Variance-to-Action Log'!$O$8:$O$23,A66,'Variance-to-Action Log'!$X$8:$X$23,"<0") -> -370.62845 | C66: =SUMIFS('Variance-to-Action Log'!$X$8:$X$23,'Variance-to-Action Log'!$O$8:$O$23,A66,'Variance-to-Action Log'!$X$8:$X$23,">0") -> 204.08461
A70: Line (open months) | B70: Cause | C70: Final action | D70: Budget – open months | E70: Forecast – open months | F70: EBITDA effect
A71: ='Variance-to-Action Log'!A8 -> Net revenue | B71: =IF('Variance-to-Action Log'!O8="","",'Variance-to-Action Log'!O8) | C71: ='Variance-to-Action Log'!T8 -> No action | D71: =SUMIFS('Assumptions & Budget'!$C67:$N67,'Assumptions & Budget'!$C$61:$N$61,">"&'Assumptions & Budget'!$C$6) -> 24116.985 | E71: =SUMIFS('Rolling Forecast'!$C12:$N12,'Rolling Forecast'!$C$5:$N$5,">"&'Assumptions & Budget'!$C$6) -> 24116.985 | F71: =E71-D71 -> 0
A72: ='Variance-to-Action Log'!A9 -> Cost of goods sold | B72: =IF('Variance-to-Action Log'!O9="","",'Variance-to-Action Log'!O9) -> Structural | C72: ='Variance-to-Action Log'!T9 -> Reforecast | D72: =SUMIFS('Assumptions & Budget'!$C68:$N68,'Assumptions & Budget'!$C$61:$N$61,">"&'Assumptions & Budget'!$C$6) -> 7476.2655 | E72: =SUMIFS('Rolling Forecast'!$C13:$N13,'Rolling Forecast'!$C$5:$N$5,">"&'Assumptions & Budget'!$C$6) -> 7021.9021 | F72: =D72-E72 -> 454.36339
A73: ='Variance-to-Action Log'!A10 -> Sales – personnel | B73: =IF('Variance-to-Action Log'!O10="","",'Variance-to-Action Log'!O10) -> Structural | C73: ='Variance-to-Action Log'!T10 -> Reforecast | D73: =SUMIFS('Assumptions & Budget'!$C72:$N72,'Assumptions & Budget'!$C$61:$N$61,">"&'Assumptions & Budget'!$C$6) -> 445.04749 | E73: =SUMIFS('Rolling Forecast'!$C17:$N17,'Rolling Forecast'!$C$5:$N$5,">"&'Assumptions & Budget'!$C$6) -> 484.2033 | F73: =D73-E73 -> -39.155811
A74: ='Variance-to-Action Log'!A11 -> Sales – marketplace & payment fees | B74: =IF('Variance-to-Action Log'!O11="","",'Variance-to-Action Log'!O11) -> Structural | C74: ='Variance-to-Action Log'!T11 -> Reforecast | D74: =SUMIFS('Assumptions & Budget'!$C73:$N73,'Assumptions & Budget'!$C$61:$N$61,">"&'Assumptions & Budget'!$C$6) -> 723.50956 | E74: =SUMIFS('Rolling Forecast'!$C18:$N18,'Rolling Forecast'!$C$5:$N$5,">"&'Assumptions & Budget'!$C$6) -> 826.42044 | F74: =D74-E74 -> -102.91087
A75: ='Variance-to-Action Log'!A12 -> Operations – personnel | B75: =IF('Variance-to-Action Log'!O12="","",'Variance-to-Action Log'!O12) | C75: ='Variance-to-Action Log'!T12 -> No action | D75: =SUMIFS('Assumptions & Budget'!$C75:$N75,'Assumptions & Budget'!$C$61:$N$61,">"&'Assumptions & Budget'!$C$6) -> 616.36349 | E75: =SUMIFS('Rolling Forecast'!$C20:$N20,'Rolling Forecast'!$C$5:$N$5,">"&'Assumptions & Budget'!$C$6) -> 616.36349 | F75: =D75-E75 -> 0
A76: ='Variance-to-Action Log'!A13 -> Operations – fulfilment & logistics | B76: =IF('Variance-to-Action Log'!O13="","",'Variance-to-Action Log'!O13) -> Structural | C76: ='Variance-to-Action Log'!T13 -> Reforecast | D76: =SUMIFS('Assumptions & Budget'!$C76:$N76,'Assumptions & Budget'!$C$61:$N$61,">"&'Assumptions & Budget'!$C$6) -> 1761.7108 | E76: =SUMIFS('Rolling Forecast'!$C21:$N21,'Rolling Forecast'!$C$5:$N$5,">"&'Assumptions & Budget'!$C$6) -> 1912.0404 | F76: =D76-E76 -> -150.32967
A77: ='Variance-to-Action Log'!A14 -> Operations – warehouse, QC & other | B77: =IF('Variance-to-Action Log'!O14="","",'Variance-to-Action Log'!O14) -> One-off | C77: ='Variance-to-Action Log'!T14 -> Ignore | D77: =SUMIFS('Assumptions & Budget'!$C77:$N77,'Assumptions & Budget'!$C$61:$N$61,">"&'Assumptions & Budget'!$C$6) -> 205.905 | E77: =SUMIFS('Rolling Forecast'!$C22:$N22,'Rolling Forecast'!$C$5:$N$5,">"&'Assumptions & Budget'!$C$6) -> 205.905 | F77: =D77-E77 -> 0
A78: ='Variance-to-Action Log'!A15 -> Marketing – personnel | B78: =IF('Variance-to-Action Log'!O15="","",'Variance-to-Action Log'!O15) | C78: ='Variance-to-Action Log'!T15 -> No action | D78: =SUMIFS('Assumptions & Budget'!$C79:$N79,'Assumptions & Budget'!$C$61:$N$61,">"&'Assumptions & Budget'!$C$6) -> 563.06524 | E78: =SUMIFS('Rolling Forecast'!$C24:$N24,'Rolling Forecast'!$C$5:$N$5,">"&'Assumptions & Budget'!$C$6) -> 563.06524 | F78: =D78-E78 -> 0
A79: ='Variance-to-Action Log'!A16 -> Marketing – performance marketing | B79: =IF('Variance-to-Action Log'!O16="","",'Variance-to-Action Log'!O16) -> Timing | C79: ='Variance-to-Action Log'!T16 -> Ignore | D79: =SUMIFS('Assumptions & Budget'!$C80:$N80,'Assumptions & Budget'!$C$61:$N$61,">"&'Assumptions & Budget'!$C$6) -> 5185.1519 | E79: =SUMIFS('Rolling Forecast'!$C25:$N25,'Rolling Forecast'!$C$5:$N$5,">"&'Assumptions & Budget'!$C$6) -> 5013.7083 | F79: =D79-E79 -> 171.44357
A80: ='Variance-to-Action Log'!A17 -> Marketing – brand & influencer | B80: =IF('Variance-to-Action Log'!O17="","",'Variance-to-Action Log'!O17) -> Structural | C80: ='Variance-to-Action Log'!T17 -> Cut spend | D80: =SUMIFS('Assumptions & Budget'!$C81:$N81,'Assumptions & Budget'!$C$61:$N$61,">"&'Assumptions & Budget'!$C$6) -> 2411.6985 | E80: =SUMIFS('Rolling Forecast'!$C26:$N26,'Rolling Forecast'!$C$5:$N$5,">"&'Assumptions & Budget'!$C$6) -> 2566.0041 | F80: =D80-E80 -> -154.30557
A81: ='Variance-to-Action Log'!A18 -> HR – personnel | B81: =IF('Variance-to-Action Log'!O18="","",'Variance-to-Action Log'!O18) | C81: ='Variance-to-Action Log'!T18 -> No action | D81: =SUMIFS('Assumptions & Budget'!$C83:$N83,'Assumptions & Budget'!$C$61:$N$61,">"&'Assumptions & Budget'!$C$6) -> 90.072 | E81: =SUMIFS('Rolling Forecast'!$C28:$N28,'Rolling Forecast'!$C$5:$N$5,">"&'Assumptions & Budget'!$C$6) -> 90.072 | F81: =D81-E81 -> 0
A82: ='Variance-to-Action Log'!A19 -> HR – recruitment, training & other | B82: =IF('Variance-to-Action Log'!O19="","",'Variance-to-Action Log'!O19) | C82: ='Variance-to-Action Log'!T19 -> No action | D82: =SUMIFS('Assumptions & Budget'!$C84:$N84,'Assumptions & Budget'!$C$61:$N$61,">"&'Assumptions & Budget'!$C$6) -> 60.7425 | E82: =SUMIFS('Rolling Forecast'!$C29:$N29,'Rolling Forecast'!$C$5:$N$5,">"&'Assumptions & Budget'!$C$6) -> 60.7425 | F82: =D82-E82 -> 0
A83: ='Variance-to-Action Log'!A20 -> IT – personnel | B83: =IF('Variance-to-Action Log'!O20="","",'Variance-to-Action Log'!O20) | C83: ='Variance-to-Action Log'!T20 -> No action | D83: =SUMIFS('Assumptions & Budget'!$C86:$N86,'Assumptions & Budget'!$C$61:$N$61,">"&'Assumptions & Budget'!$C$6) -> 589.22013 | E83: =SUMIFS('Rolling Forecast'!$C31:$N31,'Rolling Forecast'!$C$5:$N$5,">"&'Assumptions & Budget'!$C$6) -> 589.22013 | F83: =D83-E83 -> 0
A84: ='Variance-to-Action Log'!A21 -> IT – software, cloud & other | B84: =IF('Variance-to-Action Log'!O21="","",'Variance-to-Action Log'!O21) -> One-off | C84: ='Variance-to-Action Log'!T21 -> Ignore | D84: =SUMIFS('Assumptions & Budget'!$C87:$N87,'Assumptions & Budget'!$C$61:$N$61,">"&'Assumptions & Budget'!$C$6) -> 313.264 | E84: =SUMIFS('Rolling Forecast'!$C32:$N32,'Rolling Forecast'!$C$5:$N$5,">"&'Assumptions & Budget'!$C$6) -> 313.264 | F84: =D84-E84 -> 0
A85: ='Variance-to-Action Log'!A22 -> Finance – personnel | B85: =IF('Variance-to-Action Log'!O22="","",'Variance-to-Action Log'!O22) | C85: ='Variance-to-Action Log'!T22 -> No action | D85: =SUMIFS('Assumptions & Budget'!$C89:$N89,'Assumptions & Budget'!$C$61:$N$61,">"&'Assumptions & Budget'!$C$6) -> 243.7344 | E85: =SUMIFS('Rolling Forecast'!$C34:$N34,'Rolling Forecast'!$C$5:$N$5,">"&'Assumptions & Budget'!$C$6) -> 243.7344 | F85: =D85-E85 -> 0
A86: ='Variance-to-Action Log'!A23 -> Finance – professional fees, rent & admin | B86: =IF('Variance-to-Action Log'!O23="","",'Variance-to-Action Log'!O23) | C86: ='Variance-to-Action Log'!T23 -> No action | D86: =SUMIFS('Assumptions & Budget'!$C90:$N90,'Assumptions & Budget'!$C$61:$N$61,">"&'Assumptions & Budget'!$C$6) -> 372.431 | E86: =SUMIFS('Rolling Forecast'!$C35:$N35,'Rolling Forecast'!$C$5:$N$5,">"&'Assumptions & Budget'!$C$6) -> 372.431 | F86: =D86-E86 -> 0
A89: Step | B89: Value | C89: Adverse | D89: Favourable | E89: Net vs budget
A90: YTD variance | B90: ='Actual vs Budget'!O143 -> -413.17006 | C90: =MIN(B90,0) -> -413.17006 | D90: =MAX(B90,0) -> 0 | E90: =0 -> 0
...

Sheet Historical Data
A1: Historical Data – 24 months (Apr-24 to Mar-26)
A2: Fictional Indian D2C company. Amounts in ₹ lakh unless stated (100 lakh = ₹1 crore). Values are synthetic; ratios benchmarked to Honasa Consumer FY26.
A3: Blue = hard-coded input (synthetic history) · Black = formula · Green = link from another sheet
A5: Line item | B5: Unit | C5: 45383 | D5: 45413 | E5: 45444 | F5: 45474 | G5: 45505 | H5: 45536 | I5: 45566 | J5: 45597 | K5: 45627 | L5: 45658 | M5: 45689 | N5: 45717 | O5: 45748 | P5: 45778 | Q5: 45809 | R5: 45839 | S5: 45870 | T5: 45901 | U5: 45931 | V5: 45962 | W5: 45992 | X5: 46023 | Y5: 46054 | Z5: 46082 | AA5: FY25 | AB5: FY26 | AC5: YoY % / Δ pp
A6: Fiscal year (Apr–Mar) | C6: =IF(MONTH(C5)>=4,"FY"&TEXT(MOD(YEAR(C5)+1,100),"00"),"FY"&TEXT(MOD(YEAR(C5),100),"00")) -> FY25 | D6: =IF(MONTH(D5)>=4,"FY"&TEXT(MOD(YEAR(D5)+1,100),"00"),"FY"&TEXT(MOD(YEAR(D5),100),"00")) -> FY25 | E6: =IF(MONTH(E5)>=4,"FY"&TEXT(MOD(YEAR(E5)+1,100),"00"),"FY"&TEXT(MOD(YEAR(E5),100),"00")) -> FY25 | F6: =IF(MONTH(F5)>=4,"FY"&TEXT(MOD(YEAR(F5)+1,100),"00"),"FY"&TEXT(MOD(YEAR(F5),100),"00")) -> FY25 | G6: =IF(MONTH(G5)>=4,"FY"&TEXT(MOD(YEAR(G5)+1,100),"00"),"FY"&TEXT(MOD(YEAR(G5),100),"00")) -> FY25 | H6: =IF(MONTH(H5)>=4,"FY"&TEXT(MOD(YEAR(H5)+1,100),"00"),"FY"&TEXT(MOD(YEAR(H5),100),"00")) -> FY25 | I6: =IF(MONTH(I5)>=4,"FY"&TEXT(MOD(YEAR(I5)+1,100),"00"),"FY"&TEXT(MOD(YEAR(I5),100),"00")) -> FY25 | J6: =IF(MONTH(J5)>=4,"FY"&TEXT(MOD(YEAR(J5)+1,100),"00"),"FY"&TEXT(MOD(YEAR(J5),100),"00")) -> FY25 | ... Z6: =IF(MONTH(Z5)>=4,"FY"&TEXT(MOD(YEAR(Z5)+1,100),"00"),"FY"&TEXT(MOD(YEAR(Z5),100),"00")) -> FY26
A7: Revenue drivers
A8: Seasonality index | B8: index | C8: 0.95 | D8: 0.95 | E8: 0.92 | F8: 0.9 | G8: 0.95 | H8: 1 | I8: 1.2 | J8: 1.15 | K8: 1.05 | L8: 1 | M8: 0.95 | N8: 0.98 | O8: 0.95 | P8: 0.95 | Q8: 0.92 | R8: 0.9 | S8: 0.95 | T8: 1 | U8: 1.2 | V8: 1.15 | W8: 1.05 | X8: 1 | Y8: 0.95 | Z8: 0.98 | AA8: =SUMIF($C$6:$Z$6,AA$5,$C8:$Z8) -> 12 | AB8: =SUMIF($C$6:$Z$6,AB$5,$C8:$Z8) -> 12
A9: Orders (no.) | B9: no. | C9: 384145 | D9: 378011 | E9: 383658 | F9: 380891 | G9: 383424 | H9: 413579 | I9: 516519 | J9: 496039 | K9: 460674 | L9: 436168 | M9: 433711 | N9: 451452 | O9: 436271 | P9: 450446 | Q9: 435355 | R9: 419281 | S9: 458652 | T9: 475265 | U9: 598230 | V9: 569068 | W9: 523911 | X9: 499458 | Y9: 498249 | Z9: 505697 | AA9: =SUMIF($C$6:$Z$6,AA$5,$C9:$Z9) -> 5118271 | AB9: =SUMIF($C$6:$Z$6,AB$5,$C9:$Z9) -> 5869883 | AC9: =IF(AA9=0,"",AB9/AA9-1) -> 0.14684881
A10: Net AOV (₹ per order) | B10: ₹ | C10: 637.8 | D10: 640.4 | E10: 647.2 | F10: 648.6 | G10: 651.2 | H10: 653.5 | I10: 663.4 | J10: 653.7 | K10: 655.4 | L10: 656.1 | M10: 666 | N10: 671.1 | O10: 666.8 | P10: 665.2 | Q10: 667.7 | R10: 677.9 | S10: 680.8 | T10: 682.1 | U10: 677.9 | V10: 685.2 | W10: 687 | X10: 689.9 | Y10: 696 | Z10: 694.8 | AA10: =IF(AA9=0,0,AA12*100000/AA9) -> 654.36762 | AB10: =IF(AB9=0,0,AB12*100000/AB9) -> 681.44388
A11: Profit & loss (₹ lakh)
A12: Net revenue | B12: ₹ lakh | C12: =C9*C10/100000 -> 2450.0768 | D12: =D9*D10/100000 -> 2420.7824 | E12: =E9*E10/100000 -> 2483.0346 | F12: =F9*F10/100000 -> 2470.459 | G12: =G9*G10/100000 -> 2496.8571 | H12: =H9*H10/100000 -> 2702.7388 | I12: =I9*I10/100000 -> 3426.587 | J12: =J9*J10/100000 -> 3242.6069 | ... Z12: =Z9*Z10/100000 -> 3513.5828 | AA12: =SUMIF($C$6:$Z$6,AA$5,$C12:$Z12) -> 33492.308 | AB12: =SUMIF($C$6:$Z$6,AB$5,$C12:$Z12) -> 39999.959 | AC12: =IF(AA12=0,"",AB12/AA12-1) -> 0.19430284
A13: Cost of goods sold | B13: ₹ lakh | C13: 822.7 | D13: 816.3 | E13: 830.4 | F13: 817.8 | G13: 848.5 | H13: 898.6 | I13: 1136.1 | J13: 1072.4 | K13: 988 | L13: 906.4 | M13: 944.1 | N13: 957.4 | O13: 953 | P13: 956.5 | Q13: 915.8 | R13: 884.7 | S13: 964.8 | T13: 994.9 | U13: 1261 | V13: 1208.1 | W13: 1085.4 | X13: 1051.5 | Y13: 1071.2 | Z13: 1077 | AA13: =SUMIF($C$6:$Z$6,AA$5,$C13:$Z13) -> 11038.7 | AB13: =SUMIF($C$6:$Z$6,AB$5,$C13:$Z13) -> 12423.9 | AC13: =IF(AA13=0,"",AB13/AA13-1) -> 0.12548579
A14: Gross profit | B14: ₹ lakh | C14: =C12-C13 -> 1627.3768 | D14: =D12-D13 -> 1604.4824 | E14: =E12-E13 -> 1652.6346 | F14: =F12-F13 -> 1652.659 | G14: =G12-G13 -> 1648.3571 | H14: =H12-H13 -> 1804.1388 | I14: =I12-I13 -> 2290.487 | J14: =J12-J13 -> 2170.2069 | ... AB14: =AB12-AB13 -> 27576.059 | AC14: =IF(AA14=0,"",AB14/AA14-1) -> 0.22813486
A15: Gross margin % | B15: % | C15: =IF(C12=0,0,C14/C12) -> 0.66421461 | D15: =IF(D12=0,0,D14/D12) -> 0.66279498 | E15: =IF(E12=0,0,E14/E12) -> 0.6655705 | F15: =IF(F12=0,0,F14/F12) -> 0.6689684 | G15: =IF(G12=0,0,G14/G12) -> 0.66017278 | H15: =IF(H12=0,0,H14/H12) -> 0.66752244 | I15: =IF(I12=0,0,I14/I12) -> 0.6684456 | J15: =IF(J12=0,0,J14/J12) -> 0.66927845 | ... AB15: =IF(AB12=0,0,AB14/AB12) -> 0.68940218 | AC15: =AB15-AA15 -> 0.01899129
A16: Operating costs by cost centre (₹ lakh)
A17: Sales – personnel | B17: ₹ lakh | C17: 50.5 | D17: 50.6 | E17: 51.5 | F17: 51.8 | G17: 53.6 | H17: 51.1 | I17: 53.5 | J17: 53.8 | K17: 53.9 | L17: 54.5 | M17: 53.6 | N17: 55.9 | O17: 60.9 | P17: 59.6 | Q17: 61.3 | R17: 61.6 | S17: 61.8 | T17: 61 | U17: 62.6 | V17: 63.9 | W17: 64.4 | X17: 65.3 | Y17: 66 | Z17: 65.4 | AA17: =SUMIF($C$6:$Z$6,AA$5,$C17:$Z17) -> 634.3 | AB17: =SUMIF($C$6:$Z$6,AB$5,$C17:$Z17) -> 753.8 | AC17: =IF(AA17=0,"",AB17/AA17-1) -> 0.18839666
A18: Sales – marketplace & payment fees | B18: ₹ lakh | C18: 70.8 | D18: 74.1 | E18: 74.9 | F18: 76.2 | G18: 73.6 | H18: 81.6 | I18: 105.4 | J18: 96.1 | K18: 92.2 | L18: 83.6 | M18: 85.4 | N18: 89.5 | O18: 83.1 | P18: 91.6 | Q18: 85.6 | R18: 85.3 | S18: 95.5 | T18: 99 | U18: 124.9 | V18: 116.5 | W18: 106.1 | X18: 103 | Y18: 97 | Z18: 99.3 | AA18: =SUMIF($C$6:$Z$6,AA$5,$C18:$Z18) -> 1003.4 | AB18: =SUMIF($C$6:$Z$6,AB$5,$C18:$Z18) -> 1186.9 | AC18: =IF(AA18=0,"",AB18/AA18-1) -> 0.18287821
A19: Sales – total | B19: ₹ lakh | C19: =C17+C18 -> 121.3 | D19: =D17+D18 -> 124.7 | E19: =E17+E18 -> 126.4 | F19: =F17+F18 -> 128 | G19: =G17+G18 -> 127.2 | H19: =H17+H18 -> 132.7 | I19: =I17+I18 -> 158.9 | J19: =J17+J18 -> 149.9 | ... AB19: =AB17+AB18 -> 1940.7 | AC19: =IF(AA19=0,"",AB19/AA19-1) -> 0.18501557
A20: Operations – personnel | B20: ₹ lakh | C20: 79.2 | D20: 78.6 | E20: 79.5 | F20: 78.5 | G20: 79.4 | H20: 79.3 | I20: 81.5 | J20: 79.4 | K20: 81.9 | L20: 81.5 | M20: 83.4 | N20: 83.6 | O20: 90.6 | P20: 90.1 | Q20: 88.2 | R20: 90.5 | S20: 89.9 | T20: 90.6 | U20: 93.5 | V20: 93.1 | W20: 92.3 | X20: 91.9 | Y20: 93.7 | Z20: 92.9 | AA20: =SUMIF($C$6:$Z$6,AA$5,$C20:$Z20) -> 965.8 | AB20: =SUMIF($C$6:$Z$6,AB$5,$C20:$Z20) -> 1097.3 | AC20: =IF(AA20=0,"",AB20/AA20-1) -> 0.13615655
A21: Operations – fulfilment & logistics | B21: ₹ lakh | C21: 173.2 | D21: 171.5 | E21: 178.1 | F21: 173.6 | G21: 176.4 | H21: 195.4 | I21: 238.5 | J21: 233.1 | K21: 211.5 | L21: 220.1 | M21: 216.7 | N21: 228 | O21: 224.6 | P21: 223.4 | Q21: 223.4 | R21: 214.8 | S21: 232.4 | T21: 238 | U21: 307 | V21: 289.8 | W21: 270.2 | X21: 257.2 | Y21: 263 | Z21: 260.1 | AA21: =SUMIF($C$6:$Z$6,AA$5,$C21:$Z21) -> 2416.1 | AB21: =SUMIF($C$6:$Z$6,AB$5,$C21:$Z21) -> 3003.9 | AC21: =IF(AA21=0,"",AB21/AA21-1) -> 0.24328463
A22: Operations – warehouse, QC & other | B22: ₹ lakh | C22: 26.9 | D22: 28.4 | E22: 28.7 | F22: 30.2 | G22: 29.9 | H22: 29.6 | I22: 31.1 | J22: 28.2 | K22: 29.1 | L22: 119 | M22: 29.8 | N22: 28.9 | O22: 31.6 | P22: 30.8 | Q22: 29.5 | R22: 30.3 | S22: 32.2 | T22: 33.1 | U22: 34.9 | V22: 36.4 | W22: 33.4 | X22: 31.8 | Y22: 30.5 | Z22: 34 | AA22: =SUMIF($C$6:$Z$6,AA$5,$C22:$Z22) -> 439.8 | AB22: =SUMIF($C$6:$Z$6,AB$5,$C22:$Z22) -> 388.5 | AC22: =IF(AA22=0,"",AB22/AA22-1) -> -0.11664393
A23: Operations – total | B23: ₹ lakh | C23: =C20+C21+C22 -> 279.3 | D23: =D20+D21+D22 -> 278.5 | E23: =E20+E21+E22 -> 286.3 | F23: =F20+F21+F22 -> 282.3 | G23: =G20+G21+G22 -> 285.7 | H23: =H20+H21+H22 -> 304.3 | I23: =I20+I21+I22 -> 351.1 | J23: =J20+J21+J22 -> 340.7 | ... AB23: =AB20+AB21+AB22 -> 4489.7 | AC23: =IF(AA23=0,"",AB23/AA23-1) -> 0.17479132
A24: Marketing – personnel | B24: ₹ lakh | C24: 66.3 | D24: 67.1 | E24: 69 | F24: 68.6 | G24: 67.4 | H24: 69.6 | I24: 70.6 | J24: 70.9 | K24: 71.9 | L24: 70 | M24: 71.2 | N24: 73.5 | O24: 76.6 | P24: 80.8 | Q24: 79.7 | R24: 81.5 | S24: 80.1 | T24: 81.4 | U24: 83 | V24: 82.2 | W24: 83.5 | X24: 83.5 | Y24: 83.7 | Z24: 84.4 | AA24: =SUMIF($C$6:$Z$6,AA$5,$C24:$Z24) -> 836.1 | AB24: =SUMIF($C$6:$Z$6,AB$5,$C24:$Z24) -> 980.4 | AC24: =IF(AA24=0,"",AB24/AA24-1) -> 0.17258701
A25: Marketing – performance marketing | B25: ₹ lakh | C25: 575.6 | D25: 571.5 | E25: 581.7 | F25: 582.6 | G25: 601.8 | H25: 700.6 | I25: 751.3 | J25: 739.4 | K25: 676.4 | L25: 655.7 | M25: 665.7 | N25: 723.3 | O25: 668.3 | P25: 698.7 | Q25: 653.9 | R25: 627.3 | S25: 689.9 | T25: 782.1 | U25: 904.5 | V25: 854.7 | W25: 815.8 | X25: 748.2 | Y25: 781.9 | Z25: 779.8 | AA25: =SUMIF($C$6:$Z$6,AA$5,$C25:$Z25) -> 7825.6 | AB25: =SUMIF($C$6:$Z$6,AB$5,$C25:$Z25) -> 9005.1 | AC25: =IF(AA25=0,"",AB25/AA25-1) -> 0.15072327
A26: Marketing – brand & influencer | B26: ₹ lakh | C26: 255.7 | D26: 253.4 | E26: 253.4 | F26: 262.5 | G26: 255.9 | H26: 268.2 | I26: 366.1 | J26: 364.7 | K26: 331.9 | L26: 297.8 | M26: 296.9 | N26: 315.8 | O26: 314.6 | P26: 310.5 | Q26: 293.4 | R26: 303.6 | S26: 324.5 | T26: 350.7 | U26: 448.5 | V26: 408.6 | W26: 345.7 | X26: 372 | Y26: 374.8 | Z26: 352.3 | AA26: =SUMIF($C$6:$Z$6,AA$5,$C26:$Z26) -> 3522.3 | AB26: =SUMIF($C$6:$Z$6,AB$5,$C26:$Z26) -> 4199.2 | AC26: =IF(AA26=0,"",AB26/AA26-1) -> 0.19217557
A27: Marketing – total | B27: ₹ lakh | C27: =C24+C25+C26 -> 897.6 | D27: =D24+D25+D26 -> 892 | E27: =E24+E25+E26 -> 904.1 | F27: =F24+F25+F26 -> 913.7 | G27: =G24+G25+G26 -> 925.1 | H27: =H24+H25+H26 -> 1038.4 | I27: =I24+I25+I26 -> 1188 | J27: =J24+J25+J26 -> 1175 | ... AB27: =AB24+AB25+AB26 -> 14184.7 | AC27: =IF(AA27=0,"",AB27/AA27-1) -> 0.16420716
A28: HR – personnel | B28: ₹ lakh | C28: 11.2 | D28: 11.2 | E28: 11.3 | F28: 11 | G28: 11.2 | H28: 11.4 | I28: 12 | J28: 12 | K28: 12.1 | L28: 12.2 | M28: 12.1 | N28: 12.3 | O28: 13.1 | P28: 13.1 | Q28: 13.1 | R28: 13.3 | S28: 12.9 | T28: 12.7 | U28: 14.2 | V28: 13.9 | W28: 14 | X28: 14.2 | Y28: 13.7 | Z28: 13.8 | AA28: =SUMIF($C$6:$Z$6,AA$5,$C28:$Z28) -> 140 | AB28: =SUMIF($C$6:$Z$6,AB$5,$C28:$Z28) -> 162 | AC28: =IF(AA28=0,"",AB28/AA28-1) -> 0.15714286
A29: HR – recruitment, training & other | B29: ₹ lakh | C29: 8.7 | D29: 10.1 | E29: 8.3 | F29: 8.5 | G29: 9.7 | H29: 9 | I29: 9.3 | J29: 9.3 | K29: 9.7 | L29: 10.6 | M29: 9.6 | N29: 10.1 | O29: 8.1 | P29: 9.7 | Q29: 9.1 | R29: 8.9 | S29: 9.2 | T29: 9.7 | U29: 10.8 | V29: 9 | W29: 10.2 | X29: 9.8 | Y29: 10 | Z29: 11.2 | AA29: =SUMIF($C$6:$Z$6,AA$5,$C29:$Z29) -> 112.9 | AB29: =SUMIF($C$6:$Z$6,AB$5,$C29:$Z29) -> 115.7 | AC29: =IF(AA29=0,"",AB29/AA29-1) -> 0.024800709
A30: HR – total | B30: ₹ lakh | C30: =C28+C29 -> 19.9 | D30: =D28+D29 -> 21.3 | E30: =E28+E29 -> 19.6 | F30: =F28+F29 -> 19.5 | G30: =G28+G29 -> 20.9 | H30: =H28+H29 -> 20.4 | I30: =I28+I29 -> 21.3 | J30: =J28+J29 -> 21.3 | ... AB30: =AB28+AB29 -> 277.7 | AC30: =IF(AA30=0,"",AB30/AA30-1) -> 0.098062475
A31: IT – personnel | B31: ₹ lakh | C31: 61.6 | D31: 62.2 | E31: 64.7 | F31: 64.8 | G31: 64.6 | H31: 63.3 | I31: 64.1 | J31: 66 | K31: 65.6 | L31: 66.3 | M31: 68.1 | N31: 67.6 | O31: 72.9 | P31: 72.5 | Q31: 74.4 | R31: 83.3 | S31: 83.8 | T31: 84.2 | U31: 86.5 | V31: 85.3 | W31: 86.2 | X31: 85.4 | Y31: 87.3 | Z31: 88.3 | AA31: =SUMIF($C$6:$Z$6,AA$5,$C31:$Z31) -> 778.9 | AB31: =SUMIF($C$6:$Z$6,AB$5,$C31:$Z31) -> 990.1 | AC31: =IF(AA31=0,"",AB31/AA31-1) -> 0.27115162
A32: IT – software, cloud & other | B32: ₹ lakh | C32: 36.6 | D32: 37.8 | E32: 36.6 | F32: 36.3 | G32: 157.2 | H32: 38.1 | I32: 38.4 | J32: 37.3 | K32: 39.1 | L32: 39.6 | M32: 42.8 | N32: 42.4 | O32: 39.5 | P32: 40.6 | Q32: 39.6 | R32: 47.1 | S32: 48.6 | T32: 50.2 | U32: 48.1 | V32: 48.6 | W32: 47.1 | X32: 50.1 | Y32: 49.4 | Z32: 50.5 | AA32: =SUMIF($C$6:$Z$6,AA$5,$C32:$Z32) -> 582.2 | AB32: =SUMIF($C$6:$Z$6,AB$5,$C32:$Z32) -> 559.4 | AC32: =IF(AA32=0,"",AB32/AA32-1) -> -0.0391618
A33: IT – total | B33: ₹ lakh | C33: =C31+C32 -> 98.2 | D33: =D31+D32 -> 100 | E33: =E31+E32 -> 101.3 | F33: =F31+F32 -> 101.1 | G33: =G31+G32 -> 221.8 | H33: =H31+H32 -> 101.4 | I33: =I31+I32 -> 102.5 | J33: =J31+J32 -> 103.3 | ... AB33: =AB31+AB32 -> 1549.5 | AC33: =IF(AA33=0,"",AB33/AA33-1) -> 0.13841746
A34: Finance – personnel | B34: ₹ lakh | C34: 28.8 | D34: 29 | E34: 29 | F34: 29.8 | G34: 30.4 | H34: 30.9 | I34: 30.5 | J34: 30.7 | K34: 31 | L34: 32.3 | M34: 31.7 | N34: 32.3 | O34: 34 | P34: 33.7 | Q34: 33.8 | R34: 34.6 | S34: 34.8 | T34: 35.1 | U34: 35.6 | V34: 35.9 | W34: 34.6 | X34: 36.6 | Y34: 36 | Z34: 36.6 | AA34: =SUMIF($C$6:$Z$6,AA$5,$C34:$Z34) -> 366.4 | AB34: =SUMIF($C$6:$Z$6,AB$5,$C34:$Z34) -> 421.3 | AC34: =IF(AA34=0,"",AB34/AA34-1) -> 0.14983624
A35: Finance – professional fees, rent & admin | B35: ₹ lakh | C35: 50.2 | D35: 52.2 | E35: 49 | F35: 50 | G35: 58 | H35: 51.1 | I35: 51.8 | J35: 58.6 | K35: 61.4 | L35: 52.8 | M35: 54.9 | N35: 111.9 | O35: 60.4 | P35: 54.7 | Q35: 56.8 | R35: 59.5 | S35: 59.2 | T35: 57.7 | U35: 58.6 | V35: 56.1 | W35: 59.2 | X35: 59.6 | Y35: 61.2 | Z35: 59.7 | AA35: =SUMIF($C$6:$Z$6,AA$5,$C35:$Z35) -> 701.9 | AB35: =SUMIF($C$6:$Z$6,AB$5,$C35:$Z35) -> 702.7 | AC35: =IF(AA35=0,"",AB35/AA35-1) -> 0.0011397635
A36: Finance – total | B36: ₹ lakh | C36: =C34+C35 -> 79 | D36: =D34+D35 -> 81.2 | E36: =E34+E35 -> 78 | F36: =F34+F35 -> 79.8 | G36: =G34+G35 -> 88.4 | H36: =H34+H35 -> 82 | I36: =I34+I35 -> 82.3 | J36: =J34+J35 -> 89.3 | ... AB36: =AB34+AB35 -> 1124 | AC36: =IF(AA36=0,"",AB36/AA36-1) -> 0.052138912
A37: Total operating cost & profitability (₹ lakh)
A38: Total operating cost | B38: ₹ lakh | C38: =C19+C23+C27+C30+C33+C36 -> 1495.3 | D38: =D19+D23+D27+D30+D33+D36 -> 1497.7 | E38: =E19+E23+E27+E30+E33+E36 -> 1515.7 | F38: =F19+F23+F27+F30+F33+F36 -> 1524.4 | G38: =G19+G23+G27+G30+G33+G36 -> 1669.1 | H38: =H19+H23+H27+H30+H33+H36 -> 1679.2 | I38: =I19+I23+I27+I30+I33+I36 -> 1904.1 | J38: =J19+J23+J27+J30+J33+J36 -> 1879.5 | ... AB38: =AB19+AB23+AB27+AB30+AB33+AB36 -> 23566.3 | AC38: =IF(AA38=0,"",AB38/AA38-1) -> 0.15943362
A39: EBITDA | B39: ₹ lakh | C39: =C14-C38 -> 132.07681 | D39: =D14-D38 -> 106.78244 | E39: =E14-E38 -> 136.93458 | F39: =F14-F38 -> 128.25903 | G39: =G14-G38 -> -20.742912 | H39: =H14-H38 -> 124.93876 | I39: =I14-I38 -> 386.38705 | J39: =J14-J38 -> 290.70694 | ... AB39: =AB14-AB38 -> 4009.7586 | AC39: =IF(AA39=0,"",AB39/AA39-1) -> 0.88436657
A40: EBITDA margin % | B40: % | C40: =IF(C12=0,0,C39/C12) -> 0.053907212 | D40: =IF(D12=0,0,D39/D12) -> 0.044110715 | E40: =IF(E12=0,0,E39/E12) -> 0.055148075 | F40: =IF(F12=0,0,F39/F12) -> 0.051917083 | G40: =IF(G12=0,0,G39/G12) -> -0.0083076088 | H40: =IF(H12=0,0,H39/H12) -> 0.046226726 | I40: =IF(I12=0,0,I39/I12) -> 0.11276149 | J40: =IF(J12=0,0,J39/J12) -> 0.08965223 | ... AB40: =IF(AB12=0,0,AB39/AB12) -> 0.10024407 | AC40: =AB40-AA40 -> 0.036709841
A41: Depreciation & amortisation | B41: ₹ lakh | C41: 54.1 | D41: 54.9 | E41: 55.2 | F41: 55.9 | G41: 56.4 | H41: 57 | I41: 57.5 | J41: 58.4 | K41: 58.9 | L41: 60.2 | M41: 60.7 | N41: 61 | O41: 61.3 | P41: 61.9 | Q41: 63.3 | R41: 63.7 | S41: 64.5 | T41: 64.5 | U41: 66.1 | V41: 66.6 | W41: 66.8 | X41: 67.8 | Y41: 68.8 | Z41: 69.5 | AA41: =SUMIF($C$6:$Z$6,AA$5,$C41:$Z41) -> 690.2 | AB41: =SUMIF($C$6:$Z$6,AB$5,$C41:$Z41) -> 784.8 | AC41: =IF(AA41=0,"",AB41/AA41-1) -> 0.13706172
...

Sheet Assumptions & Budget
A1: Assumptions & FY27 Budget (Apr-26 to Mar-27)
A2: Part A: every driver in its own labelled cell. Part B: monthly budget built from those drivers. ₹ lakh unless stated.
A3: Yellow fill / blue text = key assumption you can change · Black = formula · Green = link from another sheet
A5: A1. General settings
A6: Actuals loaded through (first day of month) | B6: date | C6: 46266 | D6: Change when a new month of actuals is entered on the Actual vs Budget sheet
A7: Months of actuals elapsed in FY27 | B7: months | C7: =COUNTIF($C$61:$N$61,"<="&$C$6) -> 6
A8: Materiality – % of budget | B8: % | C8: 0.05 | D8: A variance is material only if it breaches BOTH the % and ₹ thresholds
A9: Materiality – absolute amount | B9: ₹ lakh | C9: 25 | D9: Tested on YTD variance and on the run-rate (look-back) variance
A10: Run-rate look-back window | B10: months | C10: 3 | D10: Used to catch variances that only started recently
A11: Timing-variance reversal period | B11: months | C11: 2 | D11: Timing variances are assumed to reverse evenly over this many forecast months
A12: Cut-spend recovery % | B12: % | C12: 0.5 | D12: Share of the run-rate overspend assumed recovered when action = Cut spend
A14: A2. Revenue drivers
A15: FY27 order growth vs FY26 | B15: % | C15: 0.09 | D15: Honasa FY26 revenue growth was about 16%; slower growth assumed as base scales
A16: Monthly net AOV growth (from Mar-26 AOV) | B16: % / month | C16: 0.003 | D16: About +3.7% a year: modest price/mix, no big price rise
A18: A3. Cost drivers
A19: Budget gross margin % | B19: % | C19: 0.69 | D19: Benchmark: Honasa FY26 gross margin about 70%; model FY26 about 69%
A20: Marketplace & payment fees % of revenue | B20: % | C20: 0.03 | D20: Held at FY26 level
A21: FY26 average fulfilment cost per order | B21: ₹ | C21: ='Historical Data'!$AB$21*100000/'Historical Data'!$AB$9 -> 51.174785 | D21: Derived from Historical Data
A22: Courier / fulfilment cost inflation for FY27 | B22: % | C22: 0.02
A23: Budget fulfilment cost per order | B23: ₹ | C23: =C21*(1+C22) -> 52.198281
A24: Performance marketing % of revenue | B24: % | C24: 0.215 | D24: FY26 about 22.4%; efficiency gains assumed. Honasa total ad spend about 33% of revenue
A25: Brand & influencer % of revenue | B25: % | C25: 0.1 | D25: FY26 about 10.3%
A26: Annual appraisal increase (effective April) | B26: % | C26: 0.08 | D26: Applied to Q4 FY26 cost per head
A27: Growth over FY26 monthly average – Operations warehouse & other | B27: % | C27: 0.06 | D27: Semi-fixed line
A28: Growth over FY26 monthly average – HR other | B28: % | C28: 0.05
A29: Growth over FY26 monthly average – IT software & other | B29: % | C29: 0.12 | D29: Higher: new tools from FY26 tech hires run a full year
A30: Growth over FY26 monthly average – Finance prof. fees & admin | B30: % | C30: 0.06
A31: Growth over FY26 monthly average – D&A | B31: % | C31: 0.08
A33: A4. Budget average monthly cost per head (Q4 FY26 actual × (1 + appraisal))
A34: Sales | B34: ₹ lakh | C34: =SUM('Historical Data'!$X$17:$Z$17)/SUM('Historical Data'!$X$44:$Z$44)*(1+$C$26) -> 1.1867933
A35: Operations | B35: ₹ lakh | C35: =SUM('Historical Data'!$X$20:$Z$20)/SUM('Historical Data'!$X$45:$Z$45)*(1+$C$26) -> 0.67288591
A36: Marketing | B36: ₹ lakh | C36: =SUM('Historical Data'!$X$24:$Z$24)/SUM('Historical Data'!$X$46:$Z$46)*(1+$C$26) -> 1.4006598
A37: HR | B37: ₹ lakh | C37: =SUM('Historical Data'!$X$28:$Z$28)/SUM('Historical Data'!$X$47:$Z$47)*(1+$C$26) -> 1.0722857
A38: IT | B38: ₹ lakh | C38: =SUM('Historical Data'!$X$31:$Z$31)/SUM('Historical Data'!$X$48:$Z$48)*(1+$C$26) -> 1.8185806
A39: Finance | B39: ₹ lakh | C39: =SUM('Historical Data'!$X$34:$Z$34)/SUM('Historical Data'!$X$49:$Z$49)*(1+$C$26) -> 1.3104
A41: A5. Line classification (drives flexed budget; documents the nature of each line)
A42: Line item | B42: Cost centre | C42: Kind | D42: Type | E42: Flex basis
A43: Net revenue | B43: – | C43: Income | D43: Volume-driven | E43: None
A44: Cost of goods sold | B44: – | C44: Cost | D44: Variable | E44: Revenue
A45: Sales – personnel | B45: Sales | C45: Cost | D45: Committed | E45: None
...

Sheet Actual vs Budget
A1: Actual vs Budget – FY27 (₹ lakh)
A2: Variances are signed so that POSITIVE = favourable and NEGATIVE = unfavourable on every line (costs: budget − actual; income: actual − budget).
A3: Actuals loaded through | C3: ='Assumptions & Budget'!$C$6 -> 46266 | D3: Months elapsed | F3: ='Assumptions & Budget'!$C$7 -> 6 | G3: Apr–Sep 2026 actuals are SIMULATED (synthetic) for demonstration. Replace blue cells with real actuals when available.
A5: Line item | B5: Unit | C5: ='Assumptions & Budget'!C61 -> 46113 | D5: ='Assumptions & Budget'!D61 -> 46143 | E5: ='Assumptions & Budget'!E61 -> 46174 | F5: ='Assumptions & Budget'!F61 -> 46204 | G5: ='Assumptions & Budget'!G61 -> 46235 | H5: ='Assumptions & Budget'!H61 -> 46266 | I5: ='Assumptions & Budget'!I61 -> 46296 | J5: ='Assumptions & Budget'!J61 -> 46327 | ... N5: ='Assumptions & Budget'!N61 -> 46447 | O5: YTD | P5: YTD var %
A6: Status | C6: =IF(C5<=$C$3,"Actual","–") -> Actual | D6: =IF(D5<=$C$3,"Actual","–") -> Actual | E6: =IF(E5<=$C$3,"Actual","–") -> Actual | F6: =IF(F5<=$C$3,"Actual","–") -> Actual | G6: =IF(G5<=$C$3,"Actual","–") -> Actual | H6: =IF(H5<=$C$3,"Actual","–") -> Actual | I6: =IF(I5<=$C$3,"Actual","–") -> – | J6: =IF(J5<=$C$3,"Actual","–") -> – | ... N6: =IF(N5<=$C$3,"Actual","–") -> –
A8: BLOCK 1 – ACTUALS (blue = input; enter monthly actuals as months close)
A9: Revenue drivers
A10: Orders (no.) | B10: no. | C10: 512605 | D10: 504896 | E10: 502172 | F10: 490655 | G10: 516802 | H10: 545874 | O10: =SUMIFS($C10:$N10,$C$5:$N$5,"<="&$C$3) -> 3073004
A11: Net AOV (₹ per order) | B11: ₹ | C11: 695.6 | D11: 693.3 | E11: 701.4 | F11: 696 | G11: 695.8 | H11: 700.1 | O11: =IF(O10=0,0,O13*100000/O10) -> 697.06677
A12: Profit & loss (₹ lakh)
A13: Net revenue | B13: ₹ lakh | C13: =C10*C11/100000 -> 3565.6804 | D13: =D10*D11/100000 -> 3500.444 | E13: =E10*E11/100000 -> 3522.2344 | F13: =F10*F11/100000 -> 3414.9588 | G13: =G10*G11/100000 -> 3595.9083 | H13: =H10*H11/100000 -> 3821.6639 | I13: =I10*I11/100000 -> 0 | J13: =J10*J11/100000 -> 0 | ... N13: =N10*N11/100000 -> 0 | O13: =SUMIFS($C13:$N13,$C$5:$N$5,"<="&$C$3) -> 21420.89
A14: Cost of goods sold | B14: ₹ lakh | C14: 1108.3 | D14: 1104.5 | E14: 1098.1 | F14: 997.8 | G14: 1036.4 | H14: 1119.8 | O14: =SUMIFS($C14:$N14,$C$5:$N$5,"<="&$C$3) -> 6464.9
A15: Gross profit | B15: ₹ lakh | C15: =C13-C14 -> 2457.3804 | D15: =D13-D14 -> 2395.944 | E15: =E13-E14 -> 2424.1344 | F15: =F13-F14 -> 2417.1588 | G15: =G13-G14 -> 2559.5083 | H15: =H13-H14 -> 2701.8639 | I15: =I13-I14 -> 0 | J15: =J13-J14 -> 0 | ... O15: =O13-O14 -> 14955.99
A16: Gross margin % | B16: % | C16: =IF(C13=0,0,C15/C13) -> 0.68917573 | D16: =IF(D13=0,0,D15/D13) -> 0.6844686 | E16: =IF(E13=0,0,E15/E13) -> 0.68823767 | F16: =IF(F13=0,0,F15/F13) -> 0.70781492 | G16: =IF(G13=0,0,G15/G13) -> 0.71178353 | H16: =IF(H13=0,0,H15/H13) -> 0.70698627 | I16: =IF(I13=0,0,I15/I13) -> 0 | J16: =IF(J13=0,0,J15/J13) -> 0 | ... O16: =IF(O13=0,0,O15/O13) -> 0.69819648
A17: Operating costs by cost centre (₹ lakh)
A18: Sales – personnel | B18: ₹ lakh | C18: 76.7 | D18: 77 | E18: 77.1 | F18: 77.5 | G18: 77.5 | H18: 80 | O18: =SUMIFS($C18:$N18,$C$5:$N$5,"<="&$C$3) -> 465.8
A19: Sales – marketplace & payment fees | B19: ₹ lakh | C19: 105.7 | D19: 101.5 | E19: 106 | F19: 120 | G19: 121.3 | H19: 129.9 | O19: =SUMIFS($C19:$N19,$C$5:$N$5,"<="&$C$3) -> 684.4
A20: Sales – total | B20: ₹ lakh | C20: =C18+C19 -> 182.4 | D20: =D18+D19 -> 178.5 | E20: =E18+E19 -> 183.1 | F20: =F18+F19 -> 197.5 | G20: =G18+G19 -> 198.8 | H20: =H18+H19 -> 209.9 | I20: =I18+I19 -> 0 | J20: =J18+J19 -> 0 | ... O20: =O18+O19 -> 1150.2
A21: Operations – personnel | B21: ₹ lakh | C21: 100.1 | D21: 101.2 | E21: 101 | F21: 100.4 | G21: 100.6 | H21: 101.4 | O21: =SUMIFS($C21:$N21,$C$5:$N$5,"<="&$C$3) -> 604.7
A22: Operations – fulfilment & logistics | B22: ₹ lakh | C22: 270.4 | D22: 266.5 | E22: 282.5 | F22: 279.7 | G22: 293.4 | H22: 306.9 | O22: =SUMIFS($C22:$N22,$C$5:$N$5,"<="&$C$3) -> 1699.4
A23: Operations – warehouse, QC & other | B23: ₹ lakh | C23: 35.7 | D23: 34.1 | E23: 34.4 | F23: 103.8 | G23: 35.9 | H23: 34.7 | O23: =SUMIFS($C23:$N23,$C$5:$N$5,"<="&$C$3) -> 278.6
A24: Operations – total | B24: ₹ lakh | C24: =C21+C22+C23 -> 406.2 | D24: =D21+D22+D23 -> 401.8 | E24: =E21+E22+E23 -> 417.9 | F24: =F21+F22+F23 -> 483.9 | G24: =G21+G22+G23 -> 429.9 | H24: =H21+H22+H23 -> 443 | I24: =I21+I22+I23 -> 0 | J24: =J21+J22+J23 -> 0 | ... O24: =O21+O22+O23 -> 2582.7
A25: Marketing – personnel | B25: ₹ lakh | C25: 90.7 | D25: 89.2 | E25: 92 | F25: 93.9 | G25: 93.5 | H25: 92.6 | O25: =SUMIFS($C25:$N25,$C$5:$N$5,"<="&$C$3) -> 551.9
A26: Marketing – performance marketing | B26: ₹ lakh | C26: 757.8 | D26: 745.1 | E26: 735.5 | F26: 718 | G26: 830.3 | H26: 948.7 | O26: =SUMIFS($C26:$N26,$C$5:$N$5,"<="&$C$3) -> 4735.4
A27: Marketing – brand & influencer | B27: ₹ lakh | C27: 360.1 | D27: 349.7 | E27: 401.3 | F27: 378 | G27: 405.6 | H27: 425.4 | O27: =SUMIFS($C27:$N27,$C$5:$N$5,"<="&$C$3) -> 2320.1
A28: Marketing – total | B28: ₹ lakh | C28: =C25+C26+C27 -> 1208.6 | D28: =D25+D26+D27 -> 1184 | E28: =E25+E26+E27 -> 1228.8 | F28: =F25+F26+F27 -> 1189.9 | G28: =G25+G26+G27 -> 1329.4 | H28: =H25+H26+H27 -> 1466.7 | I28: =I25+I26+I27 -> 0 | J28: =J25+J26+J27 -> 0 | ... O28: =O25+O26+O27 -> 7607.4
A29: HR – personnel | B29: ₹ lakh | C29: 14 | D29: 13.9 | E29: 13.9 | F29: 13.9 | G29: 13.9 | H29: 14.9 | O29: =SUMIFS($C29:$N29,$C$5:$N$5,"<="&$C$3) -> 84.5
A30: HR – recruitment, training & other | B30: ₹ lakh | C30: 10.2 | D30: 9.2 | E30: 9.7 | F30: 10.7 | G30: 10 | H30: 10.2 | O30: =SUMIFS($C30:$N30,$C$5:$N$5,"<="&$C$3) -> 60
A31: HR – total | B31: ₹ lakh | C31: =C29+C30 -> 24.2 | D31: =D29+D30 -> 23.1 | E31: =E29+E30 -> 23.6 | F31: =F29+F30 -> 24.6 | G31: =G29+G30 -> 23.9 | H31: =H29+H30 -> 25.1 | I31: =I29+I30 -> 0 | J31: =J29+J30 -> 0 | ... O31: =O29+O30 -> 144.5
A32: IT – personnel | B32: ₹ lakh | C32: 94 | D32: 94.3 | E32: 95.7 | F32: 98.9 | G32: 97.5 | H32: 99.5 | O32: =SUMIFS($C32:$N32,$C$5:$N$5,"<="&$C$3) -> 579.9
A33: IT – software, cloud & other | B33: ₹ lakh | C33: 52.2 | D33: 50.7 | E33: 138.4 | F33: 50.1 | G33: 52.2 | H33: 50.9 | O33: =SUMIFS($C33:$N33,$C$5:$N$5,"<="&$C$3) -> 394.5
A34: IT – total | B34: ₹ lakh | C34: =C32+C33 -> 146.2 | D34: =D32+D33 -> 145 | E34: =E32+E33 -> 234.1 | F34: =F32+F33 -> 149 | G34: =G32+G33 -> 149.7 | H34: =H32+H33 -> 150.4 | I34: =I32+I33 -> 0 | J34: =J32+J33 -> 0 | ... O34: =O32+O33 -> 974.4
A35: Finance – personnel | B35: ₹ lakh | C35: 39.5 | D35: 39.1 | E35: 39 | F35: 39.1 | G35: 39.2 | H35: 39.2 | O35: =SUMIFS($C35:$N35,$C$5:$N$5,"<="&$C$3) -> 235.1
A36: Finance – professional fees, rent & admin | B36: ₹ lakh | C36: 59.6 | D36: 64 | E36: 62.2 | F36: 63.3 | G36: 64.2 | H36: 62.5 | O36: =SUMIFS($C36:$N36,$C$5:$N$5,"<="&$C$3) -> 375.8
A37: Finance – total | B37: ₹ lakh | C37: =C35+C36 -> 99.1 | D37: =D35+D36 -> 103.1 | E37: =E35+E36 -> 101.2 | F37: =F35+F36 -> 102.4 | G37: =G35+G36 -> 103.4 | H37: =H35+H36 -> 101.7 | I37: =I35+I36 -> 0 | J37: =J35+J36 -> 0 | ... O37: =O35+O36 -> 610.9
A38: Total operating cost & profitability (₹ lakh)
A39: Total operating cost | B39: ₹ lakh | C39: =C20+C24+C28+C31+C34+C37 -> 2066.7 | D39: =D20+D24+D28+D31+D34+D37 -> 2035.5 | E39: =E20+E24+E28+E31+E34+E37 -> 2188.7 | F39: =F20+F24+F28+F31+F34+F37 -> 2147.3 | G39: =G20+G24+G28+G31+G34+G37 -> 2235.1 | H39: =H20+H24+H28+H31+H34+H37 -> 2396.8 | I39: =I20+I24+I28+I31+I34+I37 -> 0 | J39: =J20+J24+J28+J31+J34+J37 -> 0 | ... O39: =O20+O24+O28+O31+O34+O37 -> 13070.1
A40: EBITDA | B40: ₹ lakh | C40: =C15-C39 -> 390.68038 | D40: =D15-D39 -> 360.44397 | E40: =E15-E39 -> 235.43441 | F40: =F15-F39 -> 269.8588 | G40: =G15-G39 -> 324.40832 | H40: =H15-H39 -> 305.06387 | I40: =I15-I39 -> 0 | J40: =J15-J39 -> 0 | ... O40: =O15-O39 -> 1885.8897
A41: EBITDA margin % | B41: % | C41: =IF(C13=0,0,C40/C13) -> 0.10956685 | D41: =IF(D13=0,0,D40/D13) -> 0.10297093 | E41: =IF(E13=0,0,E40/E13) -> 0.066842345 | F41: =IF(F13=0,0,F40/F13) -> 0.079022564 | G41: =IF(G13=0,0,G40/G13) -> 0.090215959 | H41: =IF(H13=0,0,H40/H13) -> 0.079824884 | I41: =IF(I13=0,0,I40/I13) -> 0 | J41: =IF(J13=0,0,J40/J13) -> 0 | ... O41: =IF(O13=0,0,O40/O13) -> 0.088039749
A42: Depreciation & amortisation | B42: ₹ lakh | C42: 70.5 | D42: 70.3 | E42: 70.8 | F42: 69.9 | G42: 70.9 | H42: 70.8 | O42: =SUMIFS($C42:$N42,$C$5:$N$5,"<="&$C$3) -> 423.2
...

Sheet Variance-to-Action Log
A1: Variance-to-Action Log
A2: Every material variance is classified (Timing / One-off / Structural) and mapped to an action. Variances are measured against the FLEXED budget.
A3: Actuals loaded through | C3: ='Assumptions & Budget'!$C$6 -> 46266 | D3: Materiality: ≥ | F3: ='Assumptions & Budget'!$C$8 -> 0.05 | G3: and ≥ ₹ lakh | H3: ='Assumptions & Budget'!$C$9 -> 25 | I3: Look-back (months) | K3: ='Assumptions & Budget'!$C$10 -> 3
A4: Rules: Timing → Ignore (reversal built into forecast) · One-off → Ignore (excluded from run-rate) · Structural → Reforecast by default. Analyst may override with a documented reason (e.g. Cut spend). Blue cells in columns O, P, R, S are analyst inputs.
A7: Line item | B7: Cost centre | C7: Type | D7: YTD budget | E7: YTD actual | F7: YTD flexed budget | G7: YTD var vs flexed | H7: YTD var % | I7: Look-back flexed budget | J7: Look-back actual | K7: Look-back var | L7: Look-back var % | M7: Trigger | N7: Fav / Unfav | O7: Cause (analyst) | P7: Evidence / rationale | Q7: Suggested action | R7: Analyst override | S7: Override reason | T7: FINAL ACTION | U7: Run-rate adj % | V7: Forecast adj % applied | W7: Timing reversal (₹ lakh) | X7: Trigger variance (₹ lakh)
A8: Net revenue | B8: ='Assumptions & Budget'!B43 -> – | C8: ='Assumptions & Budget'!D43 -> Volume-driven | D8: ='Actual vs Budget'!O63 -> 21227.704 | E8: ='Actual vs Budget'!O13 -> 21420.89 | F8: ='Actual vs Budget'!O92 -> 21227.704 | G8: ='Actual vs Budget'!O146 -> 193.18544 | H8: ='Actual vs Budget'!P146 -> 0.0091006278 | I8: =SUMIFS('Actual vs Budget'!$C92:$N92,'Actual vs Budget'!$C$5:$N$5,">"&EDATE($C$3,-$K$3),'Actual vs Budget'!$C$5:$N$5,"<="&$C$3) -> 10718.425 | J8: =SUMIFS('Actual vs Budget'!$C13:$N13,'Actual vs Budget'!$C$5:$N$5,">"&EDATE($C$3,-$K$3),'Actual vs Budget'!$C$5:$N$5,"<="&$C$3) -> 10832.531 | K8: =SUMIFS('Actual vs Budget'!$C146:$N146,'Actual vs Budget'!$C$5:$N$5,">"&EDATE($C$3,-$K$3),'Actual vs Budget'!$C$5:$N$5,"<="&$C$3) -> 114.10595 | L8: =IF(I8=0,0,K8/I8) -> 0.010645776 | M8: =IF(AND(ABS(H8)>=$F$3,ABS(G8)>=$H$3),"YTD",IF(AND(ABS(L8)>=$F$3,ABS(K8)>=$H$3),"Run-rate","–")) -> – | N8: =IF(M8="–","–",IF(IF(M8="YTD",G8,K8)<0,"Unfav","Fav")) -> – | Q8: =IF(M8="–","No action",IF(O8="","Classify cause",IF(O8="Structural","Reforecast","Ignore"))) -> No action | T8: =IF(M8="–","No action",IF(O8="","Classify cause",IF(R8<>"",IF(S8="","Reason required",R8),Q8))) -> No action | U8: 0 | V8: =IF(T8="Reforecast",U8,IF(T8="Cut spend",U8*(1-'Assumptions & Budget'!$C$12),0)) -> 0 | W8: 0 | X8: =IF(M8="–",0,IF(M8="YTD",G8,K8)) -> 0
A9: Cost of goods sold | B9: ='Assumptions & Budget'!B44 -> – | C9: ='Assumptions & Budget'!D44 -> Variable | D9: ='Actual vs Budget'!O64 -> 6580.5883 | E9: ='Actual vs Budget'!O14 -> 6464.9 | F9: ='Actual vs Budget'!O93 -> 6640.4758 | G9: ='Actual vs Budget'!O147 -> 175.57582 | H9: ='Actual vs Budget'!P147 -> 0.026440247 | I9: =SUMIFS('Actual vs Budget'!$C93:$N93,'Actual vs Budget'!$C$5:$N$5,">"&EDATE($C$3,-$K$3),'Actual vs Budget'!$C$5:$N$5,"<="&$C$3) -> 3358.0846 | J9: =SUMIFS('Actual vs Budget'!$C14:$N14,'Actual vs Budget'!$C$5:$N$5,">"&EDATE($C$3,-$K$3),'Actual vs Budget'!$C$5:$N$5,"<="&$C$3) -> 3154 | K9: =SUMIFS('Actual vs Budget'!$C147:$N147,'Actual vs Budget'!$C$5:$N$5,">"&EDATE($C$3,-$K$3),'Actual vs Budget'!$C$5:$N$5,"<="&$C$3) -> 204.08461 | L9: =IF(I9=0,0,K9/I9) -> 0.060774111 | M9: =IF(AND(ABS(H9)>=$F$3,ABS(G9)>=$H$3),"YTD",IF(AND(ABS(L9)>=$F$3,ABS(K9)>=$H$3),"Run-rate","–")) -> Run-rate | N9: =IF(M9="–","–",IF(IF(M9="YTD",G9,K9)<0,"Unfav","Fav")) -> Fav | O9: Structural | P9: Gross margin up from Jul: supplier price renegotiation and lower inbound freight; contract runs multi-year. | Q9: =IF(M9="–","No action",IF(O9="","Classify cause",IF(O9="Structural","Reforecast","Ignore"))) -> Reforecast | T9: =IF(M9="–","No action",IF(O9="","Classify cause",IF(R9<>"",IF(S9="","Reason required",R9),Q9))) -> Reforecast | U9: =-L9 -> -0.060774111 | V9: =IF(T9="Reforecast",U9,IF(T9="Cut spend",U9*(1-'Assumptions & Budget'!$C$12),0)) -> -0.060774111 | W9: =IF(O9="Timing",G9,0) -> 0 | X9: =IF(M9="–",0,IF(M9="YTD",G9,K9)) -> 204.08461
A10: Sales – personnel | B10: ='Assumptions & Budget'!B45 -> Sales | C10: ='Assumptions & Budget'!D45 -> Committed | D10: ='Actual vs Budget'!O66 -> 429.61917 | E10: ='Actual vs Budget'!O18 -> 465.8 | F10: ='Actual vs Budget'!O95 -> 429.61917 | G10: ='Actual vs Budget'!O149 -> -36.180827 | H10: ='Actual vs Budget'!P149 -> -0.084216043 | I10: =SUMIFS('Actual vs Budget'!$C95:$N95,'Actual vs Budget'!$C$5:$N$5,">"&EDATE($C$3,-$K$3),'Actual vs Budget'!$C$5:$N$5,"<="&$C$3) -> 215.99638 | J10: =SUMIFS('Actual vs Budget'!$C18:$N18,'Actual vs Budget'!$C$5:$N$5,">"&EDATE($C$3,-$K$3),'Actual vs Budget'!$C$5:$N$5,"<="&$C$3) -> 235 | K10: =SUMIFS('Actual vs Budget'!$C149:$N149,'Actual vs Budget'!$C$5:$N$5,">"&EDATE($C$3,-$K$3),'Actual vs Budget'!$C$5:$N$5,"<="&$C$3) -> -19.00362 | L10: =IF(I10=0,0,K10/I10) -> -0.087981197 | M10: =IF(AND(ABS(H10)>=$F$3,ABS(G10)>=$H$3),"YTD",IF(AND(ABS(L10)>=$F$3,ABS(K10)>=$H$3),"Run-rate","–")) -> YTD | N10: =IF(M10="–","–",IF(IF(M10="YTD",G10,K10)<0,"Unfav","Fav")) -> Unfav | O10: Structural | P10: 5 unplanned sales hires since Apr for marketplace / quick-commerce accounts; permanent run-rate cost. | Q10: =IF(M10="–","No action",IF(O10="","Classify cause",IF(O10="Structural","Reforecast","Ignore"))) -> Reforecast | T10: =IF(M10="–","No action",IF(O10="","Classify cause",IF(R10<>"",IF(S10="","Reason required",R10),Q10))) -> Reforecast | U10: =-L10 -> 0.087981197 | V10: =IF(T10="Reforecast",U10,IF(T10="Cut spend",U10*(1-'Assumptions & Budget'!$C$12),0)) -> 0.087981197 | W10: =IF(O10="Timing",G10,0) -> 0 | X10: =IF(M10="–",0,IF(M10="YTD",G10,K10)) -> -36.180827
A11: Sales – marketplace & payment fees | B11: ='Assumptions & Budget'!B46 -> Sales | C11: ='Assumptions & Budget'!D46 -> Variable | D11: ='Actual vs Budget'!O67 -> 636.83113 | E11: ='Actual vs Budget'!O19 -> 684.4 | F11: ='Actual vs Budget'!O96 -> 642.62669 | G11: ='Actual vs Budget'!O150 -> -41.773308 | H11: ='Actual vs Budget'!P150 -> -0.065004003 | I11: =SUMIFS('Actual vs Budget'!$C96:$N96,'Actual vs Budget'!$C$5:$N$5,">"&EDATE($C$3,-$K$3),'Actual vs Budget'!$C$5:$N$5,"<="&$C$3) -> 324.97593 | J11: =SUMIFS('Actual vs Budget'!$C19:$N19,'Actual vs Budget'!$C$5:$N$5,">"&EDATE($C$3,-$K$3),'Actual vs Budget'!$C$5:$N$5,"<="&$C$3) -> 371.2 | K11: =SUMIFS('Actual vs Budget'!$C150:$N150,'Actual vs Budget'!$C$5:$N$5,">"&EDATE($C$3,-$K$3),'Actual vs Budget'!$C$5:$N$5,"<="&$C$3) -> -46.22407 | L11: =IF(I11=0,0,K11/I11) -> -0.14223844 | M11: =IF(AND(ABS(H11)>=$F$3,ABS(G11)>=$H$3),"YTD",IF(AND(ABS(L11)>=$F$3,ABS(K11)>=$H$3),"Run-rate","–")) -> YTD | N11: =IF(M11="–","–",IF(IF(M11="YTD",G11,K11)<0,"Unfav","Fav")) -> Unfav | O11: Structural | P11: Marketplace commission and platform-fee revision (~0.4 pp of sales) effective Jul. | Q11: =IF(M11="–","No action",IF(O11="","Classify cause",IF(O11="Structural","Reforecast","Ignore"))) -> Reforecast | T11: =IF(M11="–","No action",IF(O11="","Classify cause",IF(R11<>"",IF(S11="","Reason required",R11),Q11))) -> Reforecast | U11: =-L11 -> 0.14223844 | V11: =IF(T11="Reforecast",U11,IF(T11="Cut spend",U11*(1-'Assumptions & Budget'!$C$12),0)) -> 0.14223844 | W11: =IF(O11="Timing",G11,0) -> 0 | X11: =IF(M11="–",0,IF(M11="YTD",G11,K11)) -> -41.773308
A12: Operations – personnel | B12: ='Assumptions & Budget'!B47 -> Operations | C12: ='Assumptions & Budget'!D47 -> Committed | D12: ='Actual vs Budget'!O69 -> 605.59732 | E12: ='Actual vs Budget'!O21 -> 604.7 | F12: ='Actual vs Budget'!O98 -> 605.59732 | G12: ='Actual vs Budget'!O152 -> 0.89731544 | H12: ='Actual vs Budget'!P152 -> 0.0014817031 | I12: =SUMIFS('Actual vs Budget'!$C98:$N98,'Actual vs Budget'!$C$5:$N$5,">"&EDATE($C$3,-$K$3),'Actual vs Budget'!$C$5:$N$5,"<="&$C$3) -> 302.79866 | J12: =SUMIFS('Actual vs Budget'!$C21:$N21,'Actual vs Budget'!$C$5:$N$5,">"&EDATE($C$3,-$K$3),'Actual vs Budget'!$C$5:$N$5,"<="&$C$3) -> 302.4 | K12: =SUMIFS('Actual vs Budget'!$C152:$N152,'Actual vs Budget'!$C$5:$N$5,">"&EDATE($C$3,-$K$3),'Actual vs Budget'!$C$5:$N$5,"<="&$C$3) -> 0.39865772 | L12: =IF(I12=0,0,K12/I12) -> 0.0013165769 | M12: =IF(AND(ABS(H12)>=$F$3,ABS(G12)>=$H$3),"YTD",IF(AND(ABS(L12)>=$F$3,ABS(K12)>=$H$3),"Run-rate","–")) -> – | N12: =IF(M12="–","–",IF(IF(M12="YTD",G12,K12)<0,"Unfav","Fav")) -> – | Q12: =IF(M12="–","No action",IF(O12="","Classify cause",IF(O12="Structural","Reforecast","Ignore"))) -> No action | T12: =IF(M12="–","No action",IF(O12="","Classify cause",IF(R12<>"",IF(S12="","Reason required",R12),Q12))) -> No action | U12: =-L12 -> -0.0013165769 | V12: =IF(T12="Reforecast",U12,IF(T12="Cut spend",U12*(1-'Assumptions & Budget'!$C$12),0)) -> 0 | W12: =IF(O12="Timing",G12,0) -> 0 | X12: =IF(M12="–",0,IF(M12="YTD",G12,K12)) -> 0
A13: Operations – fulfilment & logistics | B13: ='Assumptions & Budget'!B48 -> Operations | C13: ='Assumptions & Budget'!D48 -> Variable | D13: ='Actual vs Budget'!O70 -> 1578.0253 | E13: ='Actual vs Budget'!O22 -> 1699.4 | F13: ='Actual vs Budget'!O99 -> 1604.0553 | G13: ='Actual vs Budget'!O153 -> -95.344749 | H13: ='Actual vs Budget'!P153 -> -0.059439816 | I13: =SUMIFS('Actual vs Budget'!$C99:$N99,'Actual vs Budget'!$C$5:$N$5,">"&EDATE($C$3,-$K$3),'Actual vs Budget'!$C$5:$N$5,"<="&$C$3) -> 810.81207 | J13: =SUMIFS('Actual vs Budget'!$C22:$N22,'Actual vs Budget'!$C$5:$N$5,">"&EDATE($C$3,-$K$3),'Actual vs Budget'!$C$5:$N$5,"<="&$C$3) -> 880 | K13: =SUMIFS('Actual vs Budget'!$C153:$N153,'Actual vs Budget'!$C$5:$N$5,">"&EDATE($C$3,-$K$3),'Actual vs Budget'!$C$5:$N$5,"<="&$C$3) -> -69.187926 | L13: =IF(I13=0,0,K13/I13) -> -0.085331642 | M13: =IF(AND(ABS(H13)>=$F$3,ABS(G13)>=$H$3),"YTD",IF(AND(ABS(L13)>=$F$3,ABS(K13)>=$H$3),"Run-rate","–")) -> YTD | N13: =IF(M13="–","–",IF(IF(M13="YTD",G13,K13)<0,"Unfav","Fav")) -> Unfav | O13: Structural | P13: Courier rate-card revision from Jun (+9% per order) plus higher RTO share. | Q13: =IF(M13="–","No action",IF(O13="","Classify cause",IF(O13="Structural","Reforecast","Ignore"))) -> Reforecast | T13: =IF(M13="–","No action",IF(O13="","Classify cause",IF(R13<>"",IF(S13="","Reason required",R13),Q13))) -> Reforecast | U13: =-L13 -> 0.085331642 | V13: =IF(T13="Reforecast",U13,IF(T13="Cut spend",U13*(1-'Assumptions & Budget'!$C$12),0)) -> 0.085331642 | W13: =IF(O13="Timing",G13,0) -> 0 | X13: =IF(M13="–",0,IF(M13="YTD",G13,K13)) -> -95.344749
A14: Operations – warehouse, QC & other | B14: ='Assumptions & Budget'!B49 -> Operations | C14: ='Assumptions & Budget'!D49 -> Committed | D14: ='Actual vs Budget'!O71 -> 205.905 | E14: ='Actual vs Budget'!O23 -> 278.6 | F14: ='Actual vs Budget'!O100 -> 205.905 | G14: ='Actual vs Budget'!O154 -> -72.695 | H14: ='Actual vs Budget'!P154 -> -0.35305116 | I14: =SUMIFS('Actual vs Budget'!$C100:$N100,'Actual vs Budget'!$C$5:$N$5,">"&EDATE($C$3,-$K$3),'Actual vs Budget'!$C$5:$N$5,"<="&$C$3) -> 102.9525 | J14: =SUMIFS('Actual vs Budget'!$C23:$N23,'Actual vs Budget'!$C$5:$N$5,">"&EDATE($C$3,-$K$3),'Actual vs Budget'!$C$5:$N$5,"<="&$C$3) -> 174.4 | K14: =SUMIFS('Actual vs Budget'!$C154:$N154,'Actual vs Budget'!$C$5:$N$5,">"&EDATE($C$3,-$K$3),'Actual vs Budget'!$C$5:$N$5,"<="&$C$3) -> -71.4475 | L14: =IF(I14=0,0,K14/I14) -> -0.69398509 | M14: =IF(AND(ABS(H14)>=$F$3,ABS(G14)>=$H$3),"YTD",IF(AND(ABS(L14)>=$F$3,ABS(K14)>=$H$3),"Run-rate","–")) -> YTD | N14: =IF(M14="–","–",IF(IF(M14="YTD",G14,K14)<0,"Unfav","Fav")) -> Unfav | O14: One-off | P14: Jul: expired-inventory write-off and warehouse re-racking; non-recurring. | Q14: =IF(M14="–","No action",IF(O14="","Classify cause",IF(O14="Structural","Reforecast","Ignore"))) -> Ignore | T14: =IF(M14="–","No action",IF(O14="","Classify cause",IF(R14<>"",IF(S14="","Reason required",R14),Q14))) -> Ignore | U14: =-L14 -> 0.69398509 | V14: =IF(T14="Reforecast",U14,IF(T14="Cut spend",U14*(1-'Assumptions & Budget'!$C$12),0)) -> 0 | W14: =IF(O14="Timing",G14,0) -> 0 | X14: =IF(M14="–",0,IF(M14="YTD",G14,K14)) -> -72.695
A15: Marketing – personnel | B15: ='Assumptions & Budget'!B50 -> Marketing | C15: ='Assumptions & Budget'!D50 -> Committed | D15: ='Actual vs Budget'!O73 -> 554.66128 | E15: ='Actual vs Budget'!O25 -> 551.9 | F15: ='Actual vs Budget'!O102 -> 554.66128 | G15: ='Actual vs Budget'!O156 -> 2.7612784 | H15: ='Actual vs Budget'!P156 -> 0.0049783146 | I15: =SUMIFS('Actual vs Budget'!$C102:$N102,'Actual vs Budget'!$C$5:$N$5,">"&EDATE($C$3,-$K$3),'Actual vs Budget'!$C$5:$N$5,"<="&$C$3) -> 281.53262 | J15: =SUMIFS('Actual vs Budget'!$C25:$N25,'Actual vs Budget'!$C$5:$N$5,">"&EDATE($C$3,-$K$3),'Actual vs Budget'!$C$5:$N$5,"<="&$C$3) -> 280 | K15: =SUMIFS('Actual vs Budget'!$C156:$N156,'Actual vs Budget'!$C$5:$N$5,">"&EDATE($C$3,-$K$3),'Actual vs Budget'!$C$5:$N$5,"<="&$C$3) -> 1.5326186 | L15: =IF(I15=0,0,K15/I15) -> 0.0054438401 | M15: =IF(AND(ABS(H15)>=$F$3,ABS(G15)>=$H$3),"YTD",IF(AND(ABS(L15)>=$F$3,ABS(K15)>=$H$3),"Run-rate","–")) -> – | N15: =IF(M15="–","–",IF(IF(M15="YTD",G15,K15)<0,"Unfav","Fav")) -> – | Q15: =IF(M15="–","No action",IF(O15="","Classify cause",IF(O15="Structural","Reforecast","Ignore"))) -> No action | T15: =IF(M15="–","No action",IF(O15="","Classify cause",IF(R15<>"",IF(S15="","Reason required",R15),Q15))) -> No action | U15: =-L15 -> -0.0054438401 | V15: =IF(T15="Reforecast",U15,IF(T15="Cut spend",U15*(1-'Assumptions & Budget'!$C$12),0)) -> 0 | W15: =IF(O15="Timing",G15,0) -> 0 | X15: =IF(M15="–",0,IF(M15="YTD",G15,K15)) -> 0
A16: Marketing – performance marketing | B16: ='Assumptions & Budget'!B51 -> Marketing | C16: ='Assumptions & Budget'!D51 -> Discretionary | D16: ='Actual vs Budget'!O74 -> 4563.9564 | E16: ='Actual vs Budget'!O26 -> 4735.4 | F16: ='Actual vs Budget'!O103 -> 4563.9564 | G16: ='Actual vs Budget'!O157 -> -171.44357 | H16: ='Actual vs Budget'!P157 -> -0.037564682 | I16: =SUMIFS('Actual vs Budget'!$C103:$N103,'Actual vs Budget'!$C$5:$N$5,">"&EDATE($C$3,-$K$3),'Actual vs Budget'!$C$5:$N$5,"<="&$C$3) -> 2304.4614 | J16: =SUMIFS('Actual vs Budget'!$C26:$N26,'Actual vs Budget'!$C$5:$N$5,">"&EDATE($C$3,-$K$3),'Actual vs Budget'!$C$5:$N$5,"<="&$C$3) -> 2497 | K16: =SUMIFS('Actual vs Budget'!$C157:$N157,'Actual vs Budget'!$C$5:$N$5,">"&EDATE($C$3,-$K$3),'Actual vs Budget'!$C$5:$N$5,"<="&$C$3) -> -192.53862 | L16: =IF(I16=0,0,K16/I16) -> -0.083550377 | M16: =IF(AND(ABS(H16)>=$F$3,ABS(G16)>=$H$3),"YTD",IF(AND(ABS(L16)>=$F$3,ABS(K16)>=$H$3),"Run-rate","–")) -> Run-rate | N16: =IF(M16="–","–",IF(IF(M16="YTD",G16,K16)<0,"Unfav","Fav")) -> Unfav | O16: Timing | P16: Sep: Diwali campaign spend pulled forward to lock in CPMs and inventory; reverses Oct–Nov. | Q16: =IF(M16="–","No action",IF(O16="","Classify cause",IF(O16="Structural","Reforecast","Ignore"))) -> Ignore | T16: =IF(M16="–","No action",IF(O16="","Classify cause",IF(R16<>"",IF(S16="","Reason required",R16),Q16))) -> Ignore | U16: =-L16 -> 0.083550377 | V16: =IF(T16="Reforecast",U16,IF(T16="Cut spend",U16*(1-'Assumptions & Budget'!$C$12),0)) -> 0 | W16: =IF(O16="Timing",G16,0) -> -171.44357 | X16: =IF(M16="–",0,IF(M16="YTD",G16,K16)) -> -192.53862
A17: Marketing – brand & influencer | B17: ='Assumptions & Budget'!B52 -> Marketing | C17: ='Assumptions & Budget'!D52 -> Discretionary | D17: ='Actual vs Budget'!O75 -> 2122.7704 | E17: ='Actual vs Budget'!O27 -> 2320.1 | F17: ='Actual vs Budget'!O104 -> 2122.7704 | G17: ='Actual vs Budget'!O158 -> -197.32957 | H17: ='Actual vs Budget'!P158 -> -0.092958507 | I17: =SUMIFS('Actual vs Budget'!$C104:$N104,'Actual vs Budget'!$C$5:$N$5,">"&EDATE($C$3,-$K$3),'Actual vs Budget'!$C$5:$N$5,"<="&$C$3) -> 1071.8425 | J17: =SUMIFS('Actual vs Budget'!$C27:$N27,'Actual vs Budget'!$C$5:$N$5,">"&EDATE($C$3,-$K$3),'Actual vs Budget'!$C$5:$N$5,"<="&$C$3) -> 1209 | K17: =SUMIFS('Actual vs Budget'!$C158:$N158,'Actual vs Budget'!$C$5:$N$5,">"&EDATE($C$3,-$K$3),'Actual vs Budget'!$C$5:$N$5,"<="&$C$3) -> -137.1575 | L17: =IF(I17=0,0,K17/I17) -> -0.12796423 | M17: =IF(AND(ABS(H17)>=$F$3,ABS(G17)>=$H$3),"YTD",IF(AND(ABS(L17)>=$F$3,ABS(K17)>=$H$3),"Run-rate","–")) -> YTD | N17: =IF(M17="–","–",IF(IF(M17="YTD",G17,K17)<0,"Unfav","Fav")) -> Unfav | O17: Structural | P17: Creator / influencer retainers stepped up from Jun beyond approved plan. | Q17: =IF(M17="–","No action",IF(O17="","Classify cause",IF(O17="Structural","Reforecast","Ignore"))) -> Reforecast | R17: Cut spend | S17: Discretionary line: brand lead agreed to cap retainers from Nov and recover ~half of the overspend. | T17: =IF(M17="–","No action",IF(O17="","Classify cause",IF(R17<>"",IF(S17="","Reason required",R17),Q17))) -> Cut spend | U17: =-L17 -> 0.12796423 | V17: =IF(T17="Reforecast",U17,IF(T17="Cut spend",U17*(1-'Assumptions & Budget'!$C$12),0)) -> 0.063982113 | W17: =IF(O17="Timing",G17,0) -> 0 | X17: =IF(M17="–",0,IF(M17="YTD",G17,K17)) -> -197.32957
A18: HR – personnel | B18: ='Assumptions & Budget'!B53 -> HR | C18: ='Assumptions & Budget'!D53 -> Committed | D18: ='Actual vs Budget'!O77 -> 90.072 | E18: ='Actual vs Budget'!O29 -> 84.5 | F18: ='Actual vs Budget'!O106 -> 90.072 | G18: ='Actual vs Budget'!O160 -> 5.572 | H18: ='Actual vs Budget'!P160 -> 0.061861622 | I18: =SUMIFS('Actual vs Budget'!$C106:$N106,'Actual vs Budget'!$C$5:$N$5,">"&EDATE($C$3,-$K$3),'Actual vs Budget'!$C$5:$N$5,"<="&$C$3) -> 45.036 | J18: =SUMIFS('Actual vs Budget'!$C29:$N29,'Actual vs Budget'!$C$5:$N$5,">"&EDATE($C$3,-$K$3),'Actual vs Budget'!$C$5:$N$5,"<="&$C$3) -> 42.7 | K18: =SUMIFS('Actual vs Budget'!$C160:$N160,'Actual vs Budget'!$C$5:$N$5,">"&EDATE($C$3,-$K$3),'Actual vs Budget'!$C$5:$N$5,"<="&$C$3) -> 2.336 | L18: =IF(I18=0,0,K18/I18) -> 0.051869615 | M18: =IF(AND(ABS(H18)>=$F$3,ABS(G18)>=$H$3),"YTD",IF(AND(ABS(L18)>=$F$3,ABS(K18)>=$H$3),"Run-rate","–")) -> – | N18: =IF(M18="–","–",IF(IF(M18="YTD",G18,K18)<0,"Unfav","Fav")) -> – | Q18: =IF(M18="–","No action",IF(O18="","Classify cause",IF(O18="Structural","Reforecast","Ignore"))) -> No action | T18: =IF(M18="–","No action",IF(O18="","Classify cause",IF(R18<>"",IF(S18="","Reason required",R18),Q18))) -> No action | U18: =-L18 -> -0.051869615 | V18: =IF(T18="Reforecast",U18,IF(T18="Cut spend",U18*(1-'Assumptions & Budget'!$C$12),0)) -> 0 | W18: =IF(O18="Timing",G18,0) -> 0 | X18: =IF(M18="–",0,IF(M18="YTD",G18,K18)) -> 0
